Workbook

Sheet Sumário
B2: SPOTVIBE — RESUMO EXECUTIVO
B3: Roadmap em 3 fases empilhadas: Validação → Venda Direta → SaaS Promoter
B5: 1. AS 3 FASES DO ROADMAP
B6: Fase | C6: Período | D6: Modelo de receita
B7: 🚀 Fase 1 — Validação | C7: set/26 a fev/27 | D7: Comissão de afiliado (5-10%)
B8: 🎫 Fase 2 — Venda Direta | C8: mar/27 a ago/27 | D8: Afiliado + Taxa de conveniência (5-8% líq.)
B9: 💎 Fase 3 — SaaS Promoter | C9: set/27 a dez/28 | D9: Afiliado + Venda direta + Assinatura R$ 49/99/149
B11: 2. INVESTIMENTO INICIAL
B12: Total bootstrap | C12: ='Investimento Inicial'!D20 -> 65700 | D12: Estrutura enxuta: legal + ferramentas + marketing inicial + capital de giro
B14: 3. RECEITA BRUTA ANUAL
B15: Ano | C15: OTIMISTA | D15: REALISTA | E15: PESSIMISTA
B16: 2026 (parcial) | C16: ='DRE Anual'!B5 -> 3836.16 | D16: ='DRE Anual'!C5 -> 524.6696 | E16: ='DRE Anual'!D5 -> 32.95875
B17: 2027 | C17: ='DRE Anual'!E5 -> 374484.79 | D17: ='DRE Anual'!F5 -> 76100.125 | E17: ='DRE Anual'!G5 -> 5910.2865
B18: 2028 | C18: ='DRE Anual'!H5 -> 4626983.5 | D18: ='DRE Anual'!I5 -> 553992.22 | E18: ='DRE Anual'!J5 -> 19210.109
B19: TOTAL 3 ANOS | C19: =SUM(C16:C18) -> 5005304.5 | D19: =SUM(D16:D18) -> 630617.02 | E19: =SUM(E16:E18) -> 25153.355
B21: 4. LUCRO LÍQUIDO ANUAL
B22: Ano | C22: OTIMISTA | D22: REALISTA | E22: PESSIMISTA
B23: 2026 (parcial) | C23: ='DRE Anual'!B13 -> -3618.9446 | D23: ='DRE Anual'!C13 -> -6710.2209 | E23: ='DRE Anual'!D13 -> -7169.233
B24: 2027 | C24: ='DRE Anual'!E13 -> 91221.124 | D24: ='DRE Anual'!F13 -> -158560.53 | E24: ='DRE Anual'!G13 -> -224082.75
B25: 2028 | C25: ='DRE Anual'!H13 -> 3537936.8 | D25: ='DRE Anual'!I13 -> 48605.135 | E25: ='DRE Anual'!J13 -> -408067.36
B26: TOTAL 3 ANOS | C26: =SUM(C23:C25) -> 3625539 | D26: =SUM(D23:D25) -> -116665.62 | E26: =SUM(E23:E25) -> -639319.34
B28: 5. INDICADORES DE VIABILIDADE
B29: Indicador | C29: OTIMISTA | D29: REALISTA | E29: PESSIMISTA
B30: VPL (3 anos) | C30: ='VPL TIR Payback'!D14 -> 11212899 | D30: ='VPL TIR Payback'!D15 -> 378095.15 | E30: ='VPL TIR Payback'!D16 -> -796155.32
B31: TIR | C31: ='VPL TIR Payback'!B19 -> 3.5044747 | D31: ='VPL TIR Payback'!B20 -> 0.64174473 | E31: ='VPL TIR Payback'!B21 -> N/A
B32: Viabilidade | C32: ='VPL TIR Payback'!E14 -> VIÁVEL | D32: ='VPL TIR Payback'!E15 -> VIÁVEL | E32: ='VPL TIR Payback'!E16 -> INVIÁVEL
B33: MRR final (dez/28) | C33: ='Métricas SaaS'!B5 -> 17550 | D33: ='Métricas SaaS'!C5 -> 8316 | E33: ='Métricas SaaS'!D5 -> 483
B34: LTV / CAC | C34: ='Métricas SaaS'!B12 -> 6 | D34: ='Métricas SaaS'!C12 -> 2.64 | E34: ='Métricas SaaS'!D12 -> -0.011979167
B36: 6. OBSERVAÇÕES IMPORTANTES
B37: 💡 Receita EMPILHADA: Fase 2 mantém afiliado da Fase 1. Fase 3 mantém ambas + adiciona SaaS.
B38: 💡 Custos POR FASE: Fase 1 ~R$ 1,8k/mês | Fase 2 ~R$ 5k/mês | Fase 3 ~R$ 14k/mês.
B39: 💡 Sócios SEM pró-labore até final de 2027. Apenas receita das vendas mantém operação.
B40: 💡 Investimento inicial enxuto: sócios programadores fazem o produto, sem CLT inicial.
B41: 💡 Gates de transição: aba 'Gates de Transição' tem checklist do que precisa bater antes de avançar.
B42: 💡 Métricas SaaS (MRR, ARR, LTV/CAC): aba 'Métricas SaaS' — essenciais para investidor.
B43: 💡 Premissas centralizadas: alterar valores azuis na aba 'Premissas' propaga para tudo.

Sheet Premissas
B2: SPOTVIBE — PREMISSAS DO ROADMAP EM 3 FASES
B3: Fase 1 (Validação) → Fase 2 (Venda Direta) → Fase 3 (SaaS) | Receitas EMPILHADAS
B5: Variável | C5: Unidade | D5: OTIMISTA | E5: REALISTA | F5: PESSIMISTA | G5: Notas
B6: 🚀 FASE 1 — VALIDAÇÃO (set/26 a fev/27, 6 meses)
B7: MAU (Usuários Ativos Mensais) — mês 1 | C7: un | D7: 4000 | E7: 2500 | F7: 800 | G7: AJUSTADO: 800 (mesmo nível do otimista)
B8: Crescimento mensal de MAU (Fase 1) | C8: % a.m. | D8: 0.4 | E8: 0.25 | F8: 0.15 | G8: Base pequena cresce rápido
B9: CTR no link de afiliado | C9: % | D9: 0.12 | E9: 0.08 | F9: 0.05 | G9: % MAU que clica em afiliado
B10: Conversão clique → compra | C10: % | D10: 0.15 | E10: 0.1 | F10: 0.06 | G10: % cliques que viram venda
B11: Ticket médio do ingresso | C11: R$ | D11: 75 | E11: 65 | F11: 55 | G11: Festas Rio (universitária/eletrônica)
B12: Comissão afiliado SpotVibe | C12: % | D12: 0.1 | E12: 0.07 | F12: 0.05 | G12: Sympla paga 10%; SuperIngressos 9%
B14: 🎫 FASE 2 — VENDA DIRETA (mar/27 a ago/27, 6 meses)
B15: Crescimento mensal de MAU (Fase 2) | C15: % a.m. | D15: 0.2 | E15: 0.12 | F15: 0.06 | G15: Base maior, cresce menos
B16: Parceiros (casas/produtores) — mês 7 | C16: un | D16: 40 | E16: 25 | F16: 5 | G16: AJUSTADO: ponte com conhecido (7-10 casas)
B17: Crescimento mensal de parceiros | C17: % a.m. | D17: 0.25 | E17: 0.18 | F17: 0.1 | G17: Aquisição de produtoras
B18: Ingressos vendidos/mês por parceiro | C18: un | D18: 30 | E18: 20 | F18: 12 | G18: Volume mensal por produtor
B19: Ticket médio venda direta | C19: R$ | D19: 85 | E19: 75 | F19: 65 | G19: Pode ser maior (festas premium)
B20: Taxa SpotVibe por ingresso direto (líq.) | C20: % | D20: 0.08 | E20: 0.07 | F20: 0.05 | G20: 10% bruto − 3% gateway = 7% líq.
B22: 💎 FASE 3 — SAAS PROMOTER (set/27 a dez/28, 16 meses)
B23: Crescimento mensal de MAU (Fase 3) | C23: % a.m. | D23: 0.1 | E23: 0.06 | F23: 0.03 | G23: Escala estabilizada
B24: Promoters assinantes — mês 13 (set/27) | C24: un | D24: 35 | E24: 20 | F24: 8 | G24: Início Fase 3
B25: Crescimento mensal de assinantes | C25: % a.m. | D25: 0.18 | E25: 0.16 | F25: 0.06 | G25: AJUSTADO: Referral + parcerias com casas (+4pp vs base)
B26: Churn mensal Promoter | C26: % a.m. | D26: 0.05 | E26: 0.05 | F26: 0.12 | G26: AJUSTADO: Plano anual com 20% desconto reduz churn (-3pp)
B27: Preço médio ponderado da assinatura | C27: R$ | D27: 90 | E27: 99 | F27: 69 | G27: AJUSTADO: Sem Basic R$49 — mix Pro 70% + Premium 30%
B29: 💵 CUSTOS OPERACIONAIS MENSAIS POR FASE
B30: Item | C30: Fase 1 (R$/mês) | D30: Fase 2 (R$/mês) | E30: Fase 3 (R$/mês) | F30: Observação
B31: Contador (Lucro Presumido) | C31: 1500 | D31: 1500 | E31: 1800 | F31: Cresce com complexidade fiscal
B32: Domínio + Cloud (free tier → pago) | C32: 0 | D32: 1500 | E32: 4000 | F32: Free tier na F1, escala depois
B33: Ferramentas SaaS | C33: 200 | D33: 500 | E33: 1000 | F33: Notion, Figma, GitHub, Slack
B34: Gateway de pagamento (custos fixos) | C34: 0 | D34: 100 | E34: 300 | F34: Stripe/Mercado Pago
B35: Marketing pago | C35: 0 | D35: 3500 | E35: 8000 | F35: Tráfego Meta/Google Rio
B36: Folha CLT (adiada — sócios fazem tudo até dez/28) | C36: 0 | D36: 5000 | E36: 15000 | F36: AJUSTADO: ZERO. Sócios fazem tudo sem CLT
B37: Pró-Labore sócios | C37: 0 | D37: 0 | E37: 0 | F37: ⚠️ Zero até final 2027
B38: Suporte (terceirizado/freela) | C38: 0 | D38: 1500 | E38: 4500 | F38: Atendimento ao produtor
B39: Materiais administrativos | C39: 100 | D39: 200 | E39: 400
B40: Contingência | C40: 0 | D40: 200 | E40: 500
B41: TOTAL MENSAL | C41: =SUM(C31:C40) -> 1800 | D41: =SUM(D31:D40) -> 14000 | E41: =SUM(E31:E40) -> 35500
B43: 📊 TRIBUTOS SOBRE RECEITA (Lucro Presumido)
B44: PIS (cumulativo) | C44: 0.0065
B45: COFINS (cumulativo) | C45: 0.03
B46: ISS (intermediação serviços) | C46: 0.03
...

Sheet Projeção Mensal
A1: SPOTVIBE — PROJEÇÃO MENSAL DETALHADA (28 MESES)
A3: ━━ CENÁRIO OTIMISTA ━━
A4: Mês operacional | B4: M1 set/26 | C4: M2 out/26 | D4: M3 nov/26 | E4: M4 dez/26 | F4: M5 jan/27 | G4: M6 fev/27 | H4: M7 mar/27 | I4: M8 abr/27 | J4: M9 mai/27 | K4: M10 jun/27 | L4: M11 jul/27 | M4: M12 ago/27 | N4: M13 set/27 | O4: M14 out/27 | P4: M15 nov/27 | Q4: M16 dez/27 | R4: M17 jan/28 | S4: M18 fev/28 | T4: M19 mar/28 | U4: M20 abr/28 | V4: M21 mai/28 | W4: M22 jun/28 | X4: M23 jul/28 | Y4: M24 ago/28 | Z4: M25 set/28 | AA4: M26 out/28 | AB4: M27 nov/28 | AC4: M28 dez/28 | AD4: TOTAL
A5: Fase do roadmap | B5: F1 | C5: F1 | D5: F1 | E5: F1 | F5: F1 | G5: F1 | H5: F2 | I5: F2 | J5: F2 | K5: F2 | L5: F2 | M5: F2 | N5: F3 | O5: F3 | P5: F3 | Q5: F3 | R5: F3 | S5: F3 | T5: F3 | U5: F3 | V5: F3 | W5: F3 | X5: F3 | Y5: F3 | Z5: F3 | AA5: F3 | AB5: F3 | AC5: F3
A7: 📊 MÉTRICAS OPERACIONAIS
A8: MAU (Usuários Ativos Mensais) | B8: =Premissas!$D$7 -> 4000 | C8: =ROUND(B8*(1+Premissas!$D$8),0) -> 5600 | D8: =ROUND(C8*(1+Premissas!$D$8),0) -> 7840 | E8: =ROUND(D8*(1+Premissas!$D$8),0) -> 10976 | F8: =ROUND(E8*(1+Premissas!$D$8),0) -> 15366 | G8: =ROUND(F8*(1+Premissas!$D$8),0) -> 21512 | H8: =ROUND(G8*(1+Premissas!$D$15),0) -> 25814 | I8: =ROUND(H8*(1+Premissas!$D$15),0) -> 30977 | J8: =ROUND(I8*(1+Premissas!$D$15),0) -> 37172 | K8: =ROUND(J8*(1+Premissas!$D$15),0) -> 44606 | L8: =ROUND(K8*(1+Premissas!$D$15),0) -> 53527 | M8: =ROUND(L8*(1+Premissas!$D$15),0) -> 64232 | N8: =ROUND(M8*(1+Premissas!$D$23),0) -> 70655 | O8: =ROUND(N8*(1+Premissas!$D$23),0) -> 77721 | P8: =ROUND(O8*(1+Premissas!$D$23),0) -> 85493 | Q8: =ROUND(P8*(1+Premissas!$D$23),0) -> 94042 | R8: =ROUND(Q8*(1+Premissas!$D$23),0) -> 103446 | S8: =ROUND(R8*(1+Premissas!$D$23),0) -> 113791 | T8: =ROUND(S8*(1+Premissas!$D$23),0) -> 125170 | U8: =ROUND(T8*(1+Premissas!$D$23),0) -> 137687 | ... AC8: =ROUND(AB8*(1+Premissas!$D$23),0) -> 295145 | AD8: =ROUND(AVERAGE(B8:AC8),0) -> 102202
A9: Parceiros ativos | B9: 0 | C9: 0 | D9: 0 | E9: 0 | F9: 0 | G9: 0 | H9: =Premissas!$D$16 -> 40 | I9: =ROUND(H9*(1+Premissas!$D$17),0) -> 50 | J9: =ROUND(I9*(1+Premissas!$D$17),0) -> 63 | K9: =ROUND(J9*(1+Premissas!$D$17),0) -> 79 | L9: =ROUND(K9*(1+Premissas!$D$17),0) -> 99 | M9: =ROUND(L9*(1+Premissas!$D$17),0) -> 124 | N9: =ROUND(M9*(1+Premissas!$D$17),0) -> 155 | O9: =ROUND(N9*(1+Premissas!$D$17),0) -> 194 | P9: =ROUND(O9*(1+Premissas!$D$17),0) -> 243 | ... AC9: =ROUND(AB9*(1+Premissas!$D$17),0) -> 4430 | AD9: =ROUND(AVERAGE(N9:AC9),0) -> 1345
A10: Assinantes Promoter (SaaS) | B10: 0 | C10: 0 | D10: 0 | E10: 0 | F10: 0 | G10: 0 | H10: 0 | I10: 0 | J10: 0 | K10: 0 | L10: 0 | M10: 0 | N10: =Premissas!$D$24 -> 35 | O10: =ROUND(N10*(1+Premissas!$D$25)*(1-Premissas!$D$26),0) -> 39 | P10: =ROUND(O10*(1+Premissas!$D$25)*(1-Premissas!$D$26),0) -> 44 | Q10: =ROUND(P10*(1+Premissas!$D$25)*(1-Premissas!$D$26),0) -> 49 | R10: =ROUND(Q10*(1+Premissas!$D$25)*(1-Premissas!$D$26),0) -> 55 | S10: =ROUND(R10*(1+Premissas!$D$25)*(1-Premissas!$D$26),0) -> 62 | T10: =ROUND(S10*(1+Premissas!$D$25)*(1-Premissas!$D$26),0) -> 70 | U10: =ROUND(T10*(1+Premissas!$D$25)*(1-Premissas!$D$26),0) -> 78 | V10: =ROUND(U10*(1+Premissas!$D$25)*(1-Premissas!$D$26),0) -> 87 | ... AC10: =ROUND(AB10*(1+Premissas!$D$25)*(1-Premissas!$D$26),0) -> 195 | AD10: =ROUND(AVERAGE(N10:AC10),0) -> 95
A12: 💰 RECEITA POR FONTE
A13: 🔗 Receita Afiliado | B13: =B8*Premissas!$D$9*Premissas!$D$10*Premissas!$D$11*Premissas!$D$12 -> 540 | C13: =C8*Premissas!$D$9*Premissas!$D$10*Premissas!$D$11*Premissas!$D$12 -> 756 | D13: =D8*Premissas!$D$9*Premissas!$D$10*Premissas!$D$11*Premissas!$D$12 -> 1058.4 | E13: =E8*Premissas!$D$9*Premissas!$D$10*Premissas!$D$11*Premissas!$D$12 -> 1481.76 | F13: =F8*Premissas!$D$9*Premissas!$D$10*Premissas!$D$11*Premissas!$D$12 -> 2074.41 | G13: =G8*Premissas!$D$9*Premissas!$D$10*Premissas!$D$11*Premissas!$D$12 -> 2904.12 | H13: =H8*Premissas!$D$9*Premissas!$D$10*Premissas!$D$11*Premissas!$D$12 -> 3484.89 | I13: =I8*Premissas!$D$9*Premissas!$D$10*Premissas!$D$11*Premissas!$D$12 -> 4181.895 | ... AC13: =AC8*Premissas!$D$9*Premissas!$D$10*Premissas!$D$11*Premissas!$D$12 -> 39844.575 | AD13: =SUM(B13:AC13) -> 386324.51
A14: 🎫 Receita Venda Direta | B14: =B9*Premissas!$D$18*Premissas!$D$19*Premissas!$D$20 -> 0 | C14: =C9*Premissas!$D$18*Premissas!$D$19*Premissas!$D$20 -> 0 | D14: =D9*Premissas!$D$18*Premissas!$D$19*Premissas!$D$20 -> 0 | E14: =E9*Premissas!$D$18*Premissas!$D$19*Premissas!$D$20 -> 0 | F14: =F9*Premissas!$D$18*Premissas!$D$19*Premissas!$D$20 -> 0 | G14: =G9*Premissas!$D$18*Premissas!$D$19*Premissas!$D$20 -> 0 | H14: =H9*Premissas!$D$18*Premissas!$D$19*Premissas!$D$20 -> 8160 | I14: =I9*Premissas!$D$18*Premissas!$D$19*Premissas!$D$20 -> 10200 | ... AC14: =AC9*Premissas!$D$18*Premissas!$D$19*Premissas!$D$20 -> 903720 | AD14: =SUM(B14:AC14) -> 4482900
A15: 💎 Receita SaaS Promoter (MRR) | B15: =B10*Premissas!$D$27 -> 0 | C15: =C10*Premissas!$D$27 -> 0 | D15: =D10*Premissas!$D$27 -> 0 | E15: =E10*Premissas!$D$27 -> 0 | F15: =F10*Premissas!$D$27 -> 0 | G15: =G10*Premissas!$D$27 -> 0 | H15: =H10*Premissas!$D$27 -> 0 | I15: =I10*Premissas!$D$27 -> 0 | ... AC15: =AC10*Premissas!$D$27 -> 17550 | AD15: =SUM(B15:AC15) -> 136080
A16: 💰 RECEITA TOTAL MENSAL | B16: =B13+B14+B15 -> 540 | C16: =C13+C14+C15 -> 756 | D16: =D13+D14+D15 -> 1058.4 | E16: =E13+E14+E15 -> 1481.76 | F16: =F13+F14+F15 -> 2074.41 | G16: =G13+G14+G15 -> 2904.12 | H16: =H13+H14+H15 -> 11644.89 | I16: =I13+I14+I15 -> 14381.895 | ... AC16: =AC13+AC14+AC15 -> 961114.57 | AD16: =SUM(B16:AC16) -> 5005304.5
A18: 💸 CUSTOS OPERACIONAIS
A19: Custos operacionais (fixo da fase) | B19: =-Premissas!$C$41 -> -1800 | C19: =-Premissas!$C$41 -> -1800 | D19: =-Premissas!$C$41 -> -1800 | E19: =-Premissas!$C$41 -> -1800 | F19: =-Premissas!$C$41 -> -1800 | G19: =-Premissas!$C$41 -> -1800 | H19: =-Premissas!$D$41 -> -14000 | I19: =-Premissas!$D$41 -> -14000 | J19: =-Premissas!$D$41 -> -14000 | K19: =-Premissas!$D$41 -> -14000 | L19: =-Premissas!$D$41 -> -14000 | M19: =-Premissas!$D$41 -> -14000 | N19: =-Premissas!$E$41 -> -35500 | O19: =-Premissas!$E$41 -> -35500 | P19: =-Premissas!$E$41 -> -35500 | Q19: =-Premissas!$E$41 -> -35500 | R19: =-Premissas!$E$41 -> -35500 | S19: =-Premissas!$E$41 -> -35500 | T19: =-Premissas!$E$41 -> -35500 | U19: =-Premissas!$E$41 -> -35500 | ... AC19: =-Premissas!$E$41 -> -35500 | AD19: =SUM(B19:AC19) -> -662800
A20: Tributos s/ Receita (PIS+COFINS+ISS) | B20: =-B16*(Premissas!$C$44+Premissas!$C$45+Premissas!$C$46) -> -35.91 | C20: =-C16*(Premissas!$C$44+Premissas!$C$45+Premissas!$C$46) -> -50.274 | D20: =-D16*(Premissas!$C$44+Premissas!$C$45+Premissas!$C$46) -> -70.3836 | E20: =-E16*(Premissas!$C$44+Premissas!$C$45+Premissas!$C$46) -> -98.53704 | F20: =-F16*(Premissas!$C$44+Premissas!$C$45+Premissas!$C$46) -> -137.94826 | G20: =-G16*(Premissas!$C$44+Premissas!$C$45+Premissas!$C$46) -> -193.12398 | H20: =-H16*(Premissas!$C$44+Premissas!$C$45+Premissas!$C$46) -> -774.38518 | I20: =-I16*(Premissas!$C$44+Premissas!$C$45+Premissas!$C$46) -> -956.39602 | ... AC20: =-AC16*(Premissas!$C$44+Premissas!$C$45+Premissas!$C$46) -> -63914.119 | AD20: =SUM(B20:AC20) -> -332852.75
A21: IRPJ + CSLL (s/ receita presumida) | B21: =IF((B16+B20+B19)>0,-B16*(Premissas!$C$47+Premissas!$C$48),0) -> 0 | C21: =IF((C16+C20+C19)>0,-C16*(Premissas!$C$47+Premissas!$C$48),0) -> 0 | D21: =IF((D16+D20+D19)>0,-D16*(Premissas!$C$47+Premissas!$C$48),0) -> 0 | E21: =IF((E16+E20+E19)>0,-E16*(Premissas!$C$47+Premissas!$C$48),0) -> 0 | F21: =IF((F16+F20+F19)>0,-F16*(Premissas!$C$47+Premissas!$C$48),0) -> -159.31469 | G21: =IF((G16+G20+G19)>0,-G16*(Premissas!$C$47+Premissas!$C$48),0) -> -223.03642 | H21: =IF((H16+H20+H19)>0,-H16*(Premissas!$C$47+Premissas!$C$48),0) -> 0 | I21: =IF((I16+I20+I19)>0,-I16*(Premissas!$C$47+Premissas!$C$48),0) -> 0 | ... AC21: =IF((AC16+AC20+AC19)>0,-AC16*(Premissas!$C$47+Premissas!$C$48),0) -> -73813.599 | AD21: =SUM(B21:AC21) -> -382113.91
A23: 📈 LUCRO/PREJUÍZO MENSAL | B23: =B16+B19+B20+B21 -> -1295.91 | C23: =C16+C19+C20+C21 -> -1094.274 | D23: =D16+D19+D20+D21 -> -811.9836 | E23: =E16+E19+E20+E21 -> -416.77704 | F23: =F16+F19+F20+F21 -> -22.852953 | G23: =G16+G19+G20+G21 -> 687.9596 | H23: =H16+H19+H20+H21 -> -3129.4952 | I23: =I16+I19+I20+I21 -> -574.50102 | ... AC23: =AC16+AC19+AC20+AC21 -> 787886.86 | AD23: =SUM(B23:AC23) -> 3627537.8
A24: 💼 Fluxo de Caixa Acumulado | B24: =B23 -> -1295.91 | C24: =B24+C23 -> -2390.184 | D24: =C24+D23 -> -3202.1676 | E24: =D24+E23 -> -3618.9446 | F24: =E24+F23 -> -3641.7976 | G24: =F24+G23 -> -2953.838 | H24: =G24+H23 -> -6083.3332 | I24: =H24+I23 -> -6657.8342 | J24: =I24+J23 -> -5348.4167 | ... AC24: =AB24+AC23 -> 3627537.8
A27: ━━ CENÁRIO REALISTA ━━
A28: Mês operacional | B28: M1 set/26 | C28: M2 out/26 | D28: M3 nov/26 | E28: M4 dez/26 | F28: M5 jan/27 | G28: M6 fev/27 | H28: M7 mar/27 | I28: M8 abr/27 | J28: M9 mai/27 | K28: M10 jun/27 | L28: M11 jul/27 | M28: M12 ago/27 | N28: M13 set/27 | O28: M14 out/27 | P28: M15 nov/27 | Q28: M16 dez/27 | R28: M17 jan/28 | S28: M18 fev/28 | T28: M19 mar/28 | U28: M20 abr/28 | V28: M21 mai/28 | W28: M22 jun/28 | X28: M23 jul/28 | Y28: M24 ago/28 | Z28: M25 set/28 | AA28: M26 out/28 | AB28: M27 nov/28 | AC28: M28 dez/28 | AD28: TOTAL
A29: Fase do roadmap | B29: F1 | C29: F1 | D29: F1 | E29: F1 | F29: F1 | G29: F1 | H29: F2 | I29: F2 | J29: F2 | K29: F2 | L29: F2 | M29: F2 | N29: F3 | O29: F3 | P29: F3 | Q29: F3 | R29: F3 | S29: F3 | T29: F3 | U29: F3 | V29: F3 | W29: F3 | X29: F3 | Y29: F3 | Z29: F3 | AA29: F3 | AB29: F3 | AC29: F3
A31: 📊 MÉTRICAS OPERACIONAIS
A32: MAU (Usuários Ativos Mensais) | B32: =Premissas!$E$7 -> 2500 | C32: =ROUND(B32*(1+Premissas!$E$8),0) -> 3125 | D32: =ROUND(C32*(1+Premissas!$E$8),0) -> 3906 | E32: =ROUND(D32*(1+Premissas!$E$8),0) -> 4883 | F32: =ROUND(E32*(1+Premissas!$E$8),0) -> 6104 | G32: =ROUND(F32*(1+Premissas!$E$8),0) -> 7630 | H32: =ROUND(G32*(1+Premissas!$E$15),0) -> 8546 | I32: =ROUND(H32*(1+Premissas!$E$15),0) -> 9572 | J32: =ROUND(I32*(1+Premissas!$E$15),0) -> 10721 | K32: =ROUND(J32*(1+Premissas!$E$15),0) -> 12008 | L32: =ROUND(K32*(1+Premissas!$E$15),0) -> 13449 | M32: =ROUND(L32*(1+Premissas!$E$15),0) -> 15063 | N32: =ROUND(M32*(1+Premissas!$E$23),0) -> 15967 | O32: =ROUND(N32*(1+Premissas!$E$23),0) -> 16925 | P32: =ROUND(O32*(1+Premissas!$E$23),0) -> 17941 | Q32: =ROUND(P32*(1+Premissas!$E$23),0) -> 19017 | R32: =ROUND(Q32*(1+Premissas!$E$23),0) -> 20158 | S32: =ROUND(R32*(1+Premissas!$E$23),0) -> 21367 | T32: =ROUND(S32*(1+Premissas!$E$23),0) -> 22649 | U32: =ROUND(T32*(1+Premissas!$E$23),0) -> 24008 | ... AC32: =ROUND(AB32*(1+Premissas!$E$23),0) -> 38266 | AD32: =ROUND(AVERAGE(B32:AC32),0) -> 18122
A33: Parceiros ativos | B33: 0 | C33: 0 | D33: 0 | E33: 0 | F33: 0 | G33: 0 | H33: =Premissas!$E$16 -> 25 | I33: =ROUND(H33*(1+Premissas!$E$17),0) -> 30 | J33: =ROUND(I33*(1+Premissas!$E$17),0) -> 35 | K33: =ROUND(J33*(1+Premissas!$E$17),0) -> 41 | L33: =ROUND(K33*(1+Premissas!$E$17),0) -> 48 | M33: =ROUND(L33*(1+Premissas!$E$17),0) -> 57 | N33: =ROUND(M33*(1+Premissas!$E$17),0) -> 67 | O33: =ROUND(N33*(1+Premissas!$E$17),0) -> 79 | P33: =ROUND(O33*(1+Premissas!$E$17),0) -> 93 | ... AC33: =ROUND(AB33*(1+Premissas!$E$17),0) -> 809 | AD33: =ROUND(AVERAGE(N33:AC33),0) -> 307
A34: Assinantes Promoter (SaaS) | B34: 0 | C34: 0 | D34: 0 | E34: 0 | F34: 0 | G34: 0 | H34: 0 | I34: 0 | J34: 0 | K34: 0 | L34: 0 | M34: 0 | N34: =Premissas!$E$24 -> 20 | O34: =ROUND(N34*(1+Premissas!$E$25)*(1-Premissas!$E$26),0) -> 22 | P34: =ROUND(O34*(1+Premissas!$E$25)*(1-Premissas!$E$26),0) -> 24 | Q34: =ROUND(P34*(1+Premissas!$E$25)*(1-Premissas!$E$26),0) -> 26 | R34: =ROUND(Q34*(1+Premissas!$E$25)*(1-Premissas!$E$26),0) -> 29 | S34: =ROUND(R34*(1+Premissas!$E$25)*(1-Premissas!$E$26),0) -> 32 | T34: =ROUND(S34*(1+Premissas!$E$25)*(1-Premissas!$E$26),0) -> 35 | U34: =ROUND(T34*(1+Premissas!$E$25)*(1-Premissas!$E$26),0) -> 39 | V34: =ROUND(U34*(1+Premissas!$E$25)*(1-Premissas!$E$26),0) -> 43 | ... AC34: =ROUND(AB34*(1+Premissas!$E$25)*(1-Premissas!$E$26),0) -> 84 | AD34: =ROUND(AVERAGE(N34:AC34),0) -> 45
A36: 💰 RECEITA POR FONTE
A37: 🔗 Receita Afiliado | B37: =B32*Premissas!$E$9*Premissas!$E$10*Premissas!$E$11*Premissas!$E$12 -> 91 | C37: =C32*Premissas!$E$9*Premissas!$E$10*Premissas!$E$11*Premissas!$E$12 -> 113.75 | D37: =D32*Premissas!$E$9*Premissas!$E$10*Premissas!$E$11*Premissas!$E$12 -> 142.1784 | E37: =E32*Premissas!$E$9*Premissas!$E$10*Premissas!$E$11*Premissas!$E$12 -> 177.7412 | F37: =F32*Premissas!$E$9*Premissas!$E$10*Premissas!$E$11*Premissas!$E$12 -> 222.1856 | G37: =G32*Premissas!$E$9*Premissas!$E$10*Premissas!$E$11*Premissas!$E$12 -> 277.732 | H37: =H32*Premissas!$E$9*Premissas!$E$10*Premissas!$E$11*Premissas!$E$12 -> 311.0744 | I37: =I32*Premissas!$E$9*Premissas!$E$10*Premissas!$E$11*Premissas!$E$12 -> 348.4208 | ... AC37: =AC32*Premissas!$E$9*Premissas!$E$10*Premissas!$E$11*Premissas!$E$12 -> 1392.8824 | AD37: =SUM(B37:AC37) -> 18470.015
A38: 🎫 Receita Venda Direta | B38: =B33*Premissas!$E$18*Premissas!$E$19*Premissas!$E$20 -> 0 | C38: =C33*Premissas!$E$18*Premissas!$E$19*Premissas!$E$20 -> 0 | D38: =D33*Premissas!$E$18*Premissas!$E$19*Premissas!$E$20 -> 0 | E38: =E33*Premissas!$E$18*Premissas!$E$19*Premissas!$E$20 -> 0 | F38: =F33*Premissas!$E$18*Premissas!$E$19*Premissas!$E$20 -> 0 | G38: =G33*Premissas!$E$18*Premissas!$E$19*Premissas!$E$20 -> 0 | H38: =H33*Premissas!$E$18*Premissas!$E$19*Premissas!$E$20 -> 2625 | I38: =I33*Premissas!$E$18*Premissas!$E$19*Premissas!$E$20 -> 3150 | ... AC38: =AC33*Premissas!$E$18*Premissas!$E$19*Premissas!$E$20 -> 84945 | AD38: =SUM(B38:AC38) -> 541065
A39: 💎 Receita SaaS Promoter (MRR) | B39: =B34*Premissas!$E$27 -> 0 | C39: =C34*Premissas!$E$27 -> 0 | D39: =D34*Premissas!$E$27 -> 0 | E39: =E34*Premissas!$E$27 -> 0 | F39: =F34*Premissas!$E$27 -> 0 | G39: =G34*Premissas!$E$27 -> 0 | H39: =H34*Premissas!$E$27 -> 0 | I39: =I34*Premissas!$E$27 -> 0 | ... AC39: =AC34*Premissas!$E$27 -> 8316 | AD39: =SUM(B39:AC39) -> 71082
A40: 💰 RECEITA TOTAL MENSAL | B40: =B37+B38+B39 -> 91 | C40: =C37+C38+C39 -> 113.75 | D40: =D37+D38+D39 -> 142.1784 | E40: =E37+E38+E39 -> 177.7412 | F40: =F37+F38+F39 -> 222.1856 | G40: =G37+G38+G39 -> 277.732 | H40: =H37+H38+H39 -> 2936.0744 | I40: =I37+I38+I39 -> 3498.4208 | ... AC40: =AC37+AC38+AC39 -> 94653.882 | AD40: =SUM(B40:AC40) -> 630617.02
A42: 💸 CUSTOS OPERACIONAIS
A43: Custos operacionais (fixo da fase) | B43: =-Premissas!$C$41 -> -1800 | C43: =-Premissas!$C$41 -> -1800 | D43: =-Premissas!$C$41 -> -1800 | E43: =-Premissas!$C$41 -> -1800 | F43: =-Premissas!$C$41 -> -1800 | G43: =-Premissas!$C$41 -> -1800 | H43: =-Premissas!$D$41 -> -14000 | I43: =-Premissas!$D$41 -> -14000 | J43: =-Premissas!$D$41 -> -14000 | K43: =-Premissas!$D$41 -> -14000 | L43: =-Premissas!$D$41 -> -14000 | M43: =-Premissas!$D$41 -> -14000 | N43: =-Premissas!$E$41 -> -35500 | O43: =-Premissas!$E$41 -> -35500 | P43: =-Premissas!$E$41 -> -35500 | Q43: =-Premissas!$E$41 -> -35500 | R43: =-Premissas!$E$41 -> -35500 | S43: =-Premissas!$E$41 -> -35500 | T43: =-Premissas!$E$41 -> -35500 | U43: =-Premissas!$E$41 -> -35500 | ... AC43: =-Premissas!$E$41 -> -35500 | AD43: =SUM(B43:AC43) -> -662800
A44: Tributos s/ Receita (PIS+COFINS+ISS) | B44: =-B40*(Premissas!$C$44+Premissas!$C$45+Premissas!$C$46) -> -6.0515 | C44: =-C40*(Premissas!$C$44+Premissas!$C$45+Premissas!$C$46) -> -7.564375 | D44: =-D40*(Premissas!$C$44+Premissas!$C$45+Premissas!$C$46) -> -9.4548636 | E44: =-E40*(Premissas!$C$44+Premissas!$C$45+Premissas!$C$46) -> -11.81979 | F44: =-F40*(Premissas!$C$44+Premissas!$C$45+Premissas!$C$46) -> -14.775342 | G44: =-G40*(Premissas!$C$44+Premissas!$C$45+Premissas!$C$46) -> -18.469178 | H44: =-H40*(Premissas!$C$44+Premissas!$C$45+Premissas!$C$46) -> -195.24895 | I44: =-I40*(Premissas!$C$44+Premissas!$C$45+Premissas!$C$46) -> -232.64498 | ... AC44: =-AC40*(Premissas!$C$44+Premissas!$C$45+Premissas!$C$46) -> -6294.4832 | AD44: =SUM(B44:AC44) -> -41936.032
A45: IRPJ + CSLL (s/ receita presumida) | B45: =IF((B40+B44+B43)>0,-B40*(Premissas!$C$47+Premissas!$C$48),0) -> 0 | C45: =IF((C40+C44+C43)>0,-C40*(Premissas!$C$47+Premissas!$C$48),0) -> 0 | D45: =IF((D40+D44+D43)>0,-D40*(Premissas!$C$47+Premissas!$C$48),0) -> 0 | E45: =IF((E40+E44+E43)>0,-E40*(Premissas!$C$47+Premissas!$C$48),0) -> 0 | F45: =IF((F40+F44+F43)>0,-F40*(Premissas!$C$47+Premissas!$C$48),0) -> 0 | G45: =IF((G40+G44+G43)>0,-G40*(Premissas!$C$47+Premissas!$C$48),0) -> 0 | H45: =IF((H40+H44+H43)>0,-H40*(Premissas!$C$47+Premissas!$C$48),0) -> 0 | I45: =IF((I40+I44+I43)>0,-I40*(Premissas!$C$47+Premissas!$C$48),0) -> 0 | ... AC45: =IF((AC40+AC44+AC43)>0,-AC40*(Premissas!$C$47+Premissas!$C$48),0) -> -7269.4182 | AD45: =SUM(B45:AC45) -> -30524.098
A47: 📈 LUCRO/PREJUÍZO MENSAL | B47: =B40+B43+B44+B45 -> -1715.0515 | C47: =C40+C43+C44+C45 -> -1693.8144 | D47: =D40+D43+D44+D45 -> -1667.2765 | E47: =E40+E43+E44+E45 -> -1634.0786 | F47: =F40+F43+F44+F45 -> -1592.5897 | G47: =G40+G43+G44+G45 -> -1540.7372 | H47: =H40+H43+H44+H45 -> -11259.175 | I47: =I40+I43+I44+I45 -> -10734.224 | ... AC47: =AC40+AC43+AC44+AC45 -> 45589.981 | AD47: =SUM(B47:AC47) -> -104643.11
A48: 💼 Fluxo de Caixa Acumulado | B48: =B47 -> -1715.0515 | C48: =B48+C47 -> -3408.8659 | D48: =C48+D47 -> -5076.1423 | E48: =D48+E47 -> -6710.2209 | F48: =E48+F47 -> -8302.8107 | G48: =F48+G47 -> -9843.5478 | H48: =G48+H47 -> -21102.722 | I48: =H48+I47 -> -31836.947 | J48: =I48+J47 -> -42042.041 | ... AC48: =AB48+AC47 -> -104643.11
A51: ━━ CENÁRIO PESSIMISTA ━━
A52: Mês operacional | B52: M1 set/26 | C52: M2 out/26 | D52: M3 nov/26 | E52: M4 dez/26 | F52: M5 jan/27 | G52: M6 fev/27 | H52: M7 mar/27 | I52: M8 abr/27 | J52: M9 mai/27 | K52: M10 jun/27 | L52: M11 jul/27 | M52: M12 ago/27 | N52: M13 set/27 | O52: M14 out/27 | P52: M15 nov/27 | Q52: M16 dez/27 | R52: M17 jan/28 | S52: M18 fev/28 | T52: M19 mar/28 | U52: M20 abr/28 | V52: M21 mai/28 | W52: M22 jun/28 | X52: M23 jul/28 | Y52: M24 ago/28 | Z52: M25 set/28 | AA52: M26 out/28 | AB52: M27 nov/28 | AC52: M28 dez/28 | AD52: TOTAL
A53: Fase do roadmap | B53: F1 | C53: F1 | D53: F1 | E53: F1 | F53: F1 | G53: F1 | H53: F2 | I53: F2 | J53: F2 | K53: F2 | L53: F2 | M53: F2 | N53: F3 | O53: F3 | P53: F3 | Q53: F3 | R53: F3 | S53: F3 | T53: F3 | U53: F3 | V53: F3 | W53: F3 | X53: F3 | Y53: F3 | Z53: F3 | AA53: F3 | AB53: F3 | AC53: F3
...

Sheet DRE Anual
A1: DRE ANUAL CONSOLIDADA
A3: Item | B3: 2026 (OTI) | C3: 2026 (REA) | D3: 2026 (PES) | E3: 2027 (OTI) | F3: 2027 (REA) | G3: 2027 (PES) | H3: 2028 (OTI) | I3: 2028 (REA) | J3: 2028 (PES)
A5: (=) Receita Bruta | B5: ='Projeção Mensal'!B16+'Projeção Mensal'!C16+'Projeção Mensal'!D16+'Projeção Mensal'!E16 -> 3836.16 | C5: ='Projeção Mensal'!B40+'Projeção Mensal'!C40+'Projeção Mensal'!D40+'Projeção Mensal'!E40 -> 524.6696 | D5: ='Projeção Mensal'!B64+'Projeção Mensal'!C64+'Projeção Mensal'!D64+'Projeção Mensal'!E64 -> 32.95875 | E5: ='Projeção Mensal'!F16+'Projeção Mensal'!G16+'Projeção Mensal'!H16+'Projeção Mensal'!I16+'Projeção Mensal'!J16+'Projeção Mensal'!K16+'Projeção Mensal'!L16+'Projeção Mensal'!M16+'Projeção Mensal'!N16+'Projeção Mensal'!O16+'Projeção Mensal'!P16+'Projeção Mensal'!Q16 -> 374484.79 | F5: ='Projeção Mensal'!F40+'Projeção Mensal'!G40+'Projeção Mensal'!H40+'Projeção Mensal'!I40+'Projeção Mensal'!J40+'Projeção Mensal'!K40+'Projeção Mensal'!L40+'Projeção Mensal'!M40+'Projeção Mensal'!N40+'Projeção Mensal'!O40+'Projeção Mensal'!P40+'Projeção Mensal'!Q40 -> 76100.125 | G5: ='Projeção Mensal'!F64+'Projeção Mensal'!G64+'Projeção Mensal'!H64+'Projeção Mensal'!I64+'Projeção Mensal'!J64+'Projeção Mensal'!K64+'Projeção Mensal'!L64+'Projeção Mensal'!M64+'Projeção Mensal'!N64+'Projeção Mensal'!O64+'Projeção Mensal'!P64+'Projeção Mensal'!Q64 -> 5910.2865 | H5: ='Projeção Mensal'!R16+'Projeção Mensal'!S16+'Projeção Mensal'!T16+'Projeção Mensal'!U16+'Projeção Mensal'!V16+'Projeção Mensal'!W16+'Projeção Mensal'!X16+'Projeção Mensal'!Y16+'Projeção Mensal'!Z16+'Projeção Mensal'!AA16+'Projeção Mensal'!AB16+'Projeção Mensal'!AC16 -> 4626983.5 | I5: ='Projeção Mensal'!R40+'Projeção Mensal'!S40+'Projeção Mensal'!T40+'Projeção Mensal'!U40+'Projeção Mensal'!V40+'Projeção Mensal'!W40+'Projeção Mensal'!X40+'Projeção Mensal'!Y40+'Projeção Mensal'!Z40+'Projeção Mensal'!AA40+'Projeção Mensal'!AB40+'Projeção Mensal'!AC40 -> 553992.22 | J5: ='Projeção Mensal'!R64+'Projeção Mensal'!S64+'Projeção Mensal'!T64+'Projeção Mensal'!U64+'Projeção Mensal'!V64+'Projeção Mensal'!W64+'Projeção Mensal'!X64+'Projeção Mensal'!Y64+'Projeção Mensal'!Z64+'Projeção Mensal'!AA64+'Projeção Mensal'!AB64+'Projeção Mensal'!AC64 -> 19210.109
A6: ↳ Receita Afiliado | B6: ='Projeção Mensal'!B13+'Projeção Mensal'!C13+'Projeção Mensal'!D13+'Projeção Mensal'!E13 -> 3836.16 | C6: ='Projeção Mensal'!B37+'Projeção Mensal'!C37+'Projeção Mensal'!D37+'Projeção Mensal'!E37 -> 524.6696 | D6: ='Projeção Mensal'!B61+'Projeção Mensal'!C61+'Projeção Mensal'!D61+'Projeção Mensal'!E61 -> 32.95875 | E6: ='Projeção Mensal'!F13+'Projeção Mensal'!G13+'Projeção Mensal'!H13+'Projeção Mensal'!I13+'Projeção Mensal'!J13+'Projeção Mensal'!K13+'Projeção Mensal'!L13+'Projeção Mensal'!M13+'Projeção Mensal'!N13+'Projeção Mensal'!O13+'Projeção Mensal'!P13+'Projeção Mensal'!Q13 -> 83850.795 | F6: ='Projeção Mensal'!F37+'Projeção Mensal'!G37+'Projeção Mensal'!H37+'Projeção Mensal'!I37+'Projeção Mensal'!J37+'Projeção Mensal'!K37+'Projeção Mensal'!L37+'Projeção Mensal'!M37+'Projeção Mensal'!N37+'Projeção Mensal'!O37+'Projeção Mensal'!P37+'Projeção Mensal'!Q37 -> 5567.1252 | G6: ='Projeção Mensal'!F61+'Projeção Mensal'!G61+'Projeção Mensal'!H61+'Projeção Mensal'!I61+'Projeção Mensal'!J61+'Projeção Mensal'!K61+'Projeção Mensal'!L61+'Projeção Mensal'!M61+'Projeção Mensal'!N61+'Projeção Mensal'!O61+'Projeção Mensal'!P61+'Projeção Mensal'!Q61 -> 204.2865 | H6: ='Projeção Mensal'!R13+'Projeção Mensal'!S13+'Projeção Mensal'!T13+'Projeção Mensal'!U13+'Projeção Mensal'!V13+'Projeção Mensal'!W13+'Projeção Mensal'!X13+'Projeção Mensal'!Y13+'Projeção Mensal'!Z13+'Projeção Mensal'!AA13+'Projeção Mensal'!AB13+'Projeção Mensal'!AC13 -> 298637.55 | I6: ='Projeção Mensal'!R37+'Projeção Mensal'!S37+'Projeção Mensal'!T37+'Projeção Mensal'!U37+'Projeção Mensal'!V37+'Projeção Mensal'!W37+'Projeção Mensal'!X37+'Projeção Mensal'!Y37+'Projeção Mensal'!Z37+'Projeção Mensal'!AA37+'Projeção Mensal'!AB37+'Projeção Mensal'!AC37 -> 12378.22 | J6: ='Projeção Mensal'!R61+'Projeção Mensal'!S61+'Projeção Mensal'!T61+'Projeção Mensal'!U61+'Projeção Mensal'!V61+'Projeção Mensal'!W61+'Projeção Mensal'!X61+'Projeção Mensal'!Y61+'Projeção Mensal'!Z61+'Projeção Mensal'!AA61+'Projeção Mensal'!AB61+'Projeção Mensal'!AC61 -> 310.10925
A7: ↳ Receita Venda Direta | B7: ='Projeção Mensal'!B14+'Projeção Mensal'!C14+'Projeção Mensal'!D14+'Projeção Mensal'!E14 -> 0 | C7: ='Projeção Mensal'!B38+'Projeção Mensal'!C38+'Projeção Mensal'!D38+'Projeção Mensal'!E38 -> 0 | D7: ='Projeção Mensal'!B62+'Projeção Mensal'!C62+'Projeção Mensal'!D62+'Projeção Mensal'!E62 -> 0 | E7: ='Projeção Mensal'!F14+'Projeção Mensal'!G14+'Projeção Mensal'!H14+'Projeção Mensal'!I14+'Projeção Mensal'!J14+'Projeção Mensal'!K14+'Projeção Mensal'!L14+'Projeção Mensal'!M14+'Projeção Mensal'!N14+'Projeção Mensal'!O14+'Projeção Mensal'!P14+'Projeção Mensal'!Q14 -> 275604 | F7: ='Projeção Mensal'!F38+'Projeção Mensal'!G38+'Projeção Mensal'!H38+'Projeção Mensal'!I38+'Projeção Mensal'!J38+'Projeção Mensal'!K38+'Projeção Mensal'!L38+'Projeção Mensal'!M38+'Projeção Mensal'!N38+'Projeção Mensal'!O38+'Projeção Mensal'!P38+'Projeção Mensal'!Q38 -> 61425 | G7: ='Projeção Mensal'!F62+'Projeção Mensal'!G62+'Projeção Mensal'!H62+'Projeção Mensal'!I62+'Projeção Mensal'!J62+'Projeção Mensal'!K62+'Projeção Mensal'!L62+'Projeção Mensal'!M62+'Projeção Mensal'!N62+'Projeção Mensal'!O62+'Projeção Mensal'!P62+'Projeção Mensal'!Q62 -> 3705 | H7: ='Projeção Mensal'!R14+'Projeção Mensal'!S14+'Projeção Mensal'!T14+'Projeção Mensal'!U14+'Projeção Mensal'!V14+'Projeção Mensal'!W14+'Projeção Mensal'!X14+'Projeção Mensal'!Y14+'Projeção Mensal'!Z14+'Projeção Mensal'!AA14+'Projeção Mensal'!AB14+'Projeção Mensal'!AC14 -> 4207296 | I7: ='Projeção Mensal'!R38+'Projeção Mensal'!S38+'Projeção Mensal'!T38+'Projeção Mensal'!U38+'Projeção Mensal'!V38+'Projeção Mensal'!W38+'Projeção Mensal'!X38+'Projeção Mensal'!Y38+'Projeção Mensal'!Z38+'Projeção Mensal'!AA38+'Projeção Mensal'!AB38+'Projeção Mensal'!AC38 -> 479640 | J7: ='Projeção Mensal'!R62+'Projeção Mensal'!S62+'Projeção Mensal'!T62+'Projeção Mensal'!U62+'Projeção Mensal'!V62+'Projeção Mensal'!W62+'Projeção Mensal'!X62+'Projeção Mensal'!Y62+'Projeção Mensal'!Z62+'Projeção Mensal'!AA62+'Projeção Mensal'!AB62+'Projeção Mensal'!AC62 -> 13104
A8: ↳ Receita SaaS Promoter | B8: ='Projeção Mensal'!B15+'Projeção Mensal'!C15+'Projeção Mensal'!D15+'Projeção Mensal'!E15 -> 0 | C8: ='Projeção Mensal'!B39+'Projeção Mensal'!C39+'Projeção Mensal'!D39+'Projeção Mensal'!E39 -> 0 | D8: ='Projeção Mensal'!B63+'Projeção Mensal'!C63+'Projeção Mensal'!D63+'Projeção Mensal'!E63 -> 0 | E8: ='Projeção Mensal'!F15+'Projeção Mensal'!G15+'Projeção Mensal'!H15+'Projeção Mensal'!I15+'Projeção Mensal'!J15+'Projeção Mensal'!K15+'Projeção Mensal'!L15+'Projeção Mensal'!M15+'Projeção Mensal'!N15+'Projeção Mensal'!O15+'Projeção Mensal'!P15+'Projeção Mensal'!Q15 -> 15030 | F8: ='Projeção Mensal'!F39+'Projeção Mensal'!G39+'Projeção Mensal'!H39+'Projeção Mensal'!I39+'Projeção Mensal'!J39+'Projeção Mensal'!K39+'Projeção Mensal'!L39+'Projeção Mensal'!M39+'Projeção Mensal'!N39+'Projeção Mensal'!O39+'Projeção Mensal'!P39+'Projeção Mensal'!Q39 -> 9108 | G8: ='Projeção Mensal'!F63+'Projeção Mensal'!G63+'Projeção Mensal'!H63+'Projeção Mensal'!I63+'Projeção Mensal'!J63+'Projeção Mensal'!K63+'Projeção Mensal'!L63+'Projeção Mensal'!M63+'Projeção Mensal'!N63+'Projeção Mensal'!O63+'Projeção Mensal'!P63+'Projeção Mensal'!Q63 -> 2001 | H8: ='Projeção Mensal'!R15+'Projeção Mensal'!S15+'Projeção Mensal'!T15+'Projeção Mensal'!U15+'Projeção Mensal'!V15+'Projeção Mensal'!W15+'Projeção Mensal'!X15+'Projeção Mensal'!Y15+'Projeção Mensal'!Z15+'Projeção Mensal'!AA15+'Projeção Mensal'!AB15+'Projeção Mensal'!AC15 -> 121050 | I8: ='Projeção Mensal'!R39+'Projeção Mensal'!S39+'Projeção Mensal'!T39+'Projeção Mensal'!U39+'Projeção Mensal'!V39+'Projeção Mensal'!W39+'Projeção Mensal'!X39+'Projeção Mensal'!Y39+'Projeção Mensal'!Z39+'Projeção Mensal'!AA39+'Projeção Mensal'!AB39+'Projeção Mensal'!AC39 -> 61974 | J8: ='Projeção Mensal'!R63+'Projeção Mensal'!S63+'Projeção Mensal'!T63+'Projeção Mensal'!U63+'Projeção Mensal'!V63+'Projeção Mensal'!W63+'Projeção Mensal'!X63+'Projeção Mensal'!Y63+'Projeção Mensal'!Z63+'Projeção Mensal'!AA63+'Projeção Mensal'!AB63+'Projeção Mensal'!AC63 -> 5796
A9: (-) Custos Operacionais | B9: =-Premissas!$C$41+-Premissas!$C$41+-Premissas!$C$41+-Premissas!$C$41 -> -7200 | C9: =-Premissas!$C$41+-Premissas!$C$41+-Premissas!$C$41+-Premissas!$C$41 -> -7200 | D9: =-Premissas!$C$41+-Premissas!$C$41+-Premissas!$C$41+-Premissas!$C$41 -> -7200 | E9: =-Premissas!$C$41+-Premissas!$C$41+-Premissas!$D$41+-Premissas!$D$41+-Premissas!$D$41+-Premissas!$D$41+-Premissas!$D$41+-Premissas!$D$41+-Premissas!$E$41+-Premissas!$E$41+-Premissas!$E$41+-Premissas!$E$41 -> -229600 | F9: =-Premissas!$C$41+-Premissas!$C$41+-Premissas!$D$41+-Premissas!$D$41+-Premissas!$D$41+-Premissas!$D$41+-Premissas!$D$41+-Premissas!$D$41+-Premissas!$E$41+-Premissas!$E$41+-Premissas!$E$41+-Premissas!$E$41 -> -229600 | G9: =-Premissas!$C$41+-Premissas!$C$41+-Premissas!$D$41+-Premissas!$D$41+-Premissas!$D$41+-Premissas!$D$41+-Premissas!$D$41+-Premissas!$D$41+-Premissas!$E$41+-Premissas!$E$41+-Premissas!$E$41+-Premissas!$E$41 -> -229600 | H9: =-Premissas!$E$41+-Premissas!$E$41+-Premissas!$E$41+-Premissas!$E$41+-Premissas!$E$41+-Premissas!$E$41+-Premissas!$E$41+-Premissas!$E$41+-Premissas!$E$41+-Premissas!$E$41+-Premissas!$E$41+-Premissas!$E$41 -> -426000 | I9: =-Premissas!$E$41+-Premissas!$E$41+-Premissas!$E$41+-Premissas!$E$41+-Premissas!$E$41+-Premissas!$E$41+-Premissas!$E$41+-Premissas!$E$41+-Premissas!$E$41+-Premissas!$E$41+-Premissas!$E$41+-Premissas!$E$41 -> -426000 | J9: =-Premissas!$E$41+-Premissas!$E$41+-Premissas!$E$41+-Premissas!$E$41+-Premissas!$E$41+-Premissas!$E$41+-Premissas!$E$41+-Premissas!$E$41+-Premissas!$E$41+-Premissas!$E$41+-Premissas!$E$41+-Premissas!$E$41 -> -426000
A10: (-) Tributos s/ Receita (PIS+COFINS+ISS) | B10: =-B5*(Premissas!$C$44+Premissas!$C$45+Premissas!$C$46) -> -255.10464 | C10: =-C5*(Premissas!$C$44+Premissas!$C$45+Premissas!$C$46) -> -34.890528 | D10: =-D5*(Premissas!$C$44+Premissas!$C$45+Premissas!$C$46) -> -2.1917569 | E10: =-E5*(Premissas!$C$44+Premissas!$C$45+Premissas!$C$46) -> -24903.239 | F10: =-F5*(Premissas!$C$44+Premissas!$C$45+Premissas!$C$46) -> -5060.6583 | G10: =-G5*(Premissas!$C$44+Premissas!$C$45+Premissas!$C$46) -> -393.03405 | H10: =-H5*(Premissas!$C$44+Premissas!$C$45+Premissas!$C$46) -> -307694.41 | I10: =-I5*(Premissas!$C$44+Premissas!$C$45+Premissas!$C$46) -> -36840.483 | J10: =-J5*(Premissas!$C$44+Premissas!$C$45+Premissas!$C$46) -> -1277.4723
A11: (=) Resultado Operacional | B11: =B5+B9+B10 -> -3618.9446 | C11: =C5+C9+C10 -> -6710.2209 | D11: =D5+D9+D10 -> -7169.233 | E11: =E5+E9+E10 -> 119981.56 | F11: =F5+F9+F10 -> -158560.53 | G11: =G5+G9+G10 -> -224082.75 | H11: =H5+H9+H10 -> 3893289.1 | I11: =I5+I9+I10 -> 91151.738 | J11: =J5+J9+J10 -> -408067.36
A12: (-) IRPJ + CSLL (se lucro) | B12: =IF(B11>0,-B5*(Premissas!$C$47+Premissas!$C$48),0) -> 0 | C12: =IF(C11>0,-C5*(Premissas!$C$47+Premissas!$C$48),0) -> 0 | D12: =IF(D11>0,-D5*(Premissas!$C$47+Premissas!$C$48),0) -> 0 | E12: =IF(E11>0,-E5*(Premissas!$C$47+Premissas!$C$48),0) -> -28760.432 | F12: =IF(F11>0,-F5*(Premissas!$C$47+Premissas!$C$48),0) -> 0 | G12: =IF(G11>0,-G5*(Premissas!$C$47+Premissas!$C$48),0) -> 0 | H12: =IF(H11>0,-H5*(Premissas!$C$47+Premissas!$C$48),0) -> -355352.34 | I12: =IF(I11>0,-I5*(Premissas!$C$47+Premissas!$C$48),0) -> -42546.603 | J12: =IF(J11>0,-J5*(Premissas!$C$47+Premissas!$C$48),0) -> 0
A13: (=) LUCRO LÍQUIDO | B13: =B11+B12 -> -3618.9446 | C13: =C11+C12 -> -6710.2209 | D13: =D11+D12 -> -7169.233 | E13: =E11+E12 -> 91221.124 | F13: =F11+F12 -> -158560.53 | G13: =G11+G12 -> -224082.75 | H13: =H11+H12 -> 3537936.8 | I13: =I11+I12 -> 48605.135 | J13: =J11+J12 -> -408067.36
A14: Margem Líquida (%) | B14: =IFERROR(B13/B5,0) -> -0.94337688 | C14: =IFERROR(C13/C5,0) -> -12.789422 | D14: =IFERROR(D13/D5,0) -> -217.52139 | E14: =IFERROR(E13/E5,0) -> 0.243591 | F14: =IFERROR(F13/F5,0) -> -2.0835778 | G14: =IFERROR(G13/G5,0) -> -37.914025 | H14: =IFERROR(H13/H5,0) -> 0.76463138 | I14: =IFERROR(I13/I5,0) -> 0.087736133 | J14: =IFERROR(J13/J5,0) -> -21.242324

Sheet Métricas SaaS
A1: MÉTRICAS SAAS — MRR, ARR, LTV, CAC
A2: Indicadores-chave para o investidor avaliar a saúde do SaaS (Fase 3)
A4: Métrica | B4: Otimista | C4: Realista | D4: Pessimista
A5: MRR final (dez/28) | B5: ='Projeção Mensal'!AC15 -> 17550 | C5: ='Projeção Mensal'!AC39 -> 8316 | D5: ='Projeção Mensal'!AC63 -> 483
A6: ARR (Anual Recurring Revenue) | B6: =B5*12 -> 210600 | C6: =C5*12 -> 99792 | D6: =D5*12 -> 5796
A7: Assinantes Promoter (dez/28) | B7: ='Projeção Mensal'!AC10 -> 195 | C7: ='Projeção Mensal'!AC34 -> 84 | D7: ='Projeção Mensal'!AC58 -> 7
A8: ARPU (preço médio mensal) | B8: =Premissas!$D$27 -> 90 | C8: =Premissas!$E$27 -> 99 | D8: =Premissas!$F$27 -> 69
A9: Churn mensal | B9: =Premissas!$D$26 -> 0.05 | C9: =Premissas!$E$26 -> 0.05 | D9: =Premissas!$F$26 -> 0.12
A10: LTV (Lifetime Value) | B10: =IFERROR(B8/B9,0) -> 1800 | C10: =IFERROR(C8/C9,0) -> 1980 | D10: =IFERROR(D8/D9,0) -> 575
A11: CAC estimado (Marketing F3 / aquisição) | B11: =IFERROR(3000*16/('Projeção Mensal'!AC10-Premissas!D24),0) -> 300 | C11: =IFERROR(3000*16/('Projeção Mensal'!AC34-Premissas!E24),0) -> 750 | D11: =IFERROR(3000*16/('Projeção Mensal'!AC58-Premissas!F24),0) -> -48000
A12: LTV / CAC (saudável > 3x) | B12: =IFERROR(B10/B11,0) -> 6 | C12: =IFERROR(C10/C11,0) -> 2.64 | D12: =IFERROR(D10/D11,0) -> -0.011979167
A13: Payback do CAC (meses) | B13: =IFERROR(B11/B8,0) -> 3.3333333 | C13: =IFERROR(C11/C8,0) -> 7.5757576 | D13: =IFERROR(D11/D8,0) -> -695.65217
A15: 📝 NOTAS:
A16: LTV = ARPU / Churn. Quanto receita esperada de um assinante ao longo da vida.
A17: CAC estimado: custo de marketing da Fase 3 ÷ assinantes adquiridos.
A18: LTV / CAC > 3x é saudável. < 1x = está pagando mais pra adquirir do que ganha.
A19: Payback do CAC < 12 meses é saudável. Quanto tempo o assinante leva pra pagar o custo de aquisição.

Sheet Gates de Transição
B2: GATES DE TRANSIÇÃO ENTRE FASES
B3: NÃO avance para a próxima fase até bater TODOS os critérios desta lista
B5: 🚀 FASE 1 → FASE 2 (Validação para Venda Direta)
B6: Critério | C6: Status | D6: Detalhe
B7: 2.000+ MAU consistentes por 2 meses | C7: ☐ Não atingido | D7: Prova que tem audiência recorrente, não só curiosos
B8: CTR do afiliado > 8% | C8: ☐ Não atingido | D8: Prova que os usuários confiam no redirect
B9: Pelo menos 3 produtores pediram pra listar evento | C9: ☐ Não atingido | D9: Demanda orgânica = sinal forte
B10: Dados de conversão documentados | C10: ☐ Não atingido | D10: Ex: 'X% dos cliques viraram compra no Sympla'
B12: 🎫 FASE 2 → FASE 3 (Venda Direta para SaaS)
B13: Critério | C13: Status | D13: Detalhe
B14: 10.000+ MAU | C14: ☐ Não atingido | D14: Volume suficiente pra justificar infraestrutura de pagamento
B15: 15+ produtores parceiros ativos | C15: ☐ Não atingido | D15: Pipeline de eventos estável sem depender de curadoria manual
B16: Receita mensal > R$ 5.000 consistente | C16: ☐ Não atingido | D16: Prova que o modelo sustenta operação
B17: Chargeback < 2% | C17: ☐ Não atingido | D17: Operação de pagamento saudável e controlada
B19: 💎 FASE 3 — GATES DE ESCALA SaaS
B20: Critério | C20: Status | D20: Detalhe
B21: 30.000+ MAU | C21: ☐ Não atingido | D21: Audiência grande o suficiente pra promoter ver valor em pagar
B22: 100+ promoters assinantes | C22: ☐ Não atingido | D22: SaaS viável com base sólida de MRR
B23: MRR > R$ 10.000 | C23: ☐ Não atingido | D23: Receita recorrente cobre custos e permite contratar
B24: NPS dos promoters > 40 | C24: ☐ Não atingido | D24: Promoters satisfeitos = retenção + indicação orgânica
B25: LTV/CAC > 3x | C25: ☐ Não atingido | D25: Unit economics saudável — escala viável
B26: Churn < 8% mensal | C26: ☐ Não atingido | D26: Retenção saudável de assinantes
B29: ⚠️ RISCOS POR FASE
B30: [FASE 1] Poucos eventos = app vazio = usuário desinstala | C30: Solução: foco em 1 região (Zona Sul + Lapa) com curadoria impecável
B31: [FASE 2] Chargeback e fraude em pagamentos | C31: Solução: comece com 2-3 parceiros de confiança, teste o fluxo antes de escalar
B32: [FASE 2] Produtor não recebe a tempo e perde confiança | C32: Solução: contratos claros com prazo de repasse (D+2)
B33: [FASE 2] QR Code falha na porta do evento | C33: Solução: teste exaustivo + plano B (lista manual)
B34: [FASE 3] Promoter cancela se não vender o suficiente pelo app | C34: Solução: trial grátis 30 dias, valor real antes de cobrar
B35: [FASE 3] Competição com ferramentas próprias do Sympla/Ingresse | C35: Solução: diferenciar por experiência, integração nativa e UX superior

Sheet Investimento Inicial
A1: INVESTIMENTO INICIAL — BOOTSTRAP
A2: Sócios programadores fazem o produto, sem CLT inicial, infra free tier
A4: Item | B4: Preço unit. | C4: Qtd | D4: Total | E4: Observação
A5: LEGAL E ABERTURA
A6: Abertura de empresa (MEI/ME) + contabilidade inicial | B6: 1500 | C6: 1 | D6: =B6*C6 -> 1500 | E6: CNPJ, alvará, contrato social
A7: Assessoria jurídica (termos de uso, LGPD) | B7: 3000 | C7: 1 | D7: =B7*C7 -> 3000 | E7: Termos, privacidade, contratos com produtores
A8: Registro de marca INPI | B8: 1500 | C8: 1 | D8: =B8*C8 -> 1500 | E8: Proteger o nome SpotVibe
A9: INFRAESTRUTURA E FERRAMENTAS
A10: Domínio + emails + SSL (1º ano) | B10: 800 | C10: 1 | D10: =B10*C10 -> 800 | E10: spotvibe.com.br + Google Workspace básico
A11: Identidade visual + logo + brand kit | B11: 8000 | C11: 1 | D11: =B11*C11 -> 8000 | E11: Designer freela (ou um dos sócios)
A12: Licenças de software 1º ano | B12: 2400 | C12: 1 | D12: =B12*C12 -> 2400 | E12: Figma, GitHub, Notion, Adobe (mínimos)
A13: MARKETING DE LANÇAMENTO
A14: Tráfego pago lançamento (RJ + SP + capitais) | B14: 12000 | C14: 1 | D14: =B14*C14 -> 12000 | E14: Lançamento + aquisição inicial
A15: Material gráfico + brindes networking | B15: 1500 | C15: 1 | D15: =B15*C15 -> 1500 | E15: Adesivos, cards, networking nas casas
A16: CAPITAL DE GIRO
A17: Reserva operacional (Fase 1 + custos de expansão) | B17: 25000 | C17: 1 | D17: =B17*C17 -> 25000 | E17: Cobertura de custo fixo até receita estabilizar
A18: Reserva contingência (multi-cidade) | B18: 10000 | C18: 1 | D18: =B18*C18 -> 10000 | E18: Imprevistos legais/operacionais
A20: TOTAL INVESTIMENTO INICIAL | D20: =SUM(D5:D18) -> 65700

Sheet VPL TIR Payback
A1: INDICADORES DE VIABILIDADE — VPL, TIR, PAYBACK (5 ANOS)
A3: Investimento Inicial | B3: ='Investimento Inicial'!$D$20 -> 65700
A4: Taxa de Desconto (WACC) | B4: =Premissas!$C$52 -> 0.18
A6: FLUXOS DE CAIXA ANUAIS — 5 ANOS (Lucro Líquido)
A7: Cenário | B7: 2026 | C7: 2027 | D7: 2028 | E7: 2029 | F7: 2030
A8: OTIMISTA | B8: ='Projeção 5 Anos'!B15 -> -3618.9446 | C8: ='Projeção 5 Anos'!E15 -> 91221.124 | D8: ='Projeção 5 Anos'!H15 -> 3537936.8 | E8: ='Projeção 5 Anos'!K15 -> 6759598.6 | F8: ='Projeção 5 Anos'!N15 -> 12757290
A9: REALISTA | B9: ='Projeção 5 Anos'!C15 -> -6710.2209 | C9: ='Projeção 5 Anos'!F15 -> -158560.53 | D9: ='Projeção 5 Anos'!I15 -> 48605.135 | E9: ='Projeção 5 Anos'!L15 -> 393785.82 | F9: ='Projeção 5 Anos'!O15 -> 756480.4
A10: PESSIMISTA | B10: ='Projeção 5 Anos'!D15 -> -7169.233 | C10: ='Projeção 5 Anos'!G15 -> -224082.75 | D10: ='Projeção 5 Anos'!J15 -> -408067.36 | E10: ='Projeção 5 Anos'!M15 -> -277945.13 | F10: ='Projeção 5 Anos'!P15 -> -392861.9
A12: VPL (Valor Presente Líquido) — 5 ANOS
A13: Cenário | B13: Fluxo desc. | C13: Investimento | D13: VPL | E13: Viabilidade
A14: OTIMISTA | B14: =NPV($B$4,B8:F8) -> 11278599 | C14: =$B$3 -> 65700 | D14: =B14-C14 -> 11212899 | E14: =IF(D14>0,"VIÁVEL","INVIÁVEL") -> VIÁVEL
A15: REALISTA | B15: =NPV($B$4,B9:F9) -> 443795.15 | C15: =$B$3 -> 65700 | D15: =B15-C15 -> 378095.15 | E15: =IF(D15>0,"VIÁVEL","INVIÁVEL") -> VIÁVEL
A16: PESSIMISTA | B16: =NPV($B$4,B10:F10) -> -730455.32 | C16: =$B$3 -> 65700 | D16: =B16-C16 -> -796155.32 | E16: =IF(D16>0,"VIÁVEL","INVIÁVEL") -> INVIÁVEL
A18: TIR (Taxa Interna de Retorno)
A19: OTIMISTA | B19: =H32 -> 3.5044747
A20: REALISTA | B20: =H33 -> 0.64174473
A21: PESSIMISTA | B21: =H34 -> N/A
A23: PAYBACK — Fluxo de Caixa Acumulado (5 ANOS)
A24: Cenário | B24: Início | C24: Fim 2026 | D24: Fim 2027 | E24: Fim 2028 | F24: Fim 2029 | G24: Fim 2030
A25: OTIMISTA | B25: =-$B$3 -> -65700 | C25: =B25+B8 -> -69318.945 | D25: =C25+C8 -> 21902.179 | E25: =D25+D8 -> 3559839 | F25: =E25+E8 -> 10319438 | G25: =F25+F8 -> 23076727
A26: REALISTA | B26: =-$B$3 -> -65700 | C26: =B26+B9 -> -72410.221 | D26: =C26+C9 -> -230970.75 | E26: =D26+D9 -> -182365.62 | F26: =E26+E9 -> 211420.2 | G26: =F26+F9 -> 967900.59
A27: PESSIMISTA | B27: =-$B$3 -> -65700 | C27: =B27+B10 -> -72869.233 | D27: =C27+C10 -> -296951.98 | E27: =D27+D10 -> -705019.34 | F27: =E27+E10 -> -982964.47 | G27: =F27+F10 -> -1375826.4
A30: TABELA AUXILIAR TIR
A31: Cenário | B31: Ano 0 | C31: 2026 | D31: 2027 | E31: 2028 | F31: 2029 | G31: 2030 | H31: TIR
A32: OTIMISTA | B32: =-$B$3 -> -65700 | C32: =B8 -> -3618.9446 | D32: =C8 -> 91221.124 | E32: =D8 -> 3537936.8 | F32: =E8 -> 6759598.6 | G32: =F8 -> 12757290 | H32: =IFERROR(IRR(B32:G32),"N/A") -> 3.5044747
A33: REALISTA | B33: =-$B$3 -> -65700 | C33: =B9 -> -6710.2209 | D33: =C9 -> -158560.53 | E33: =D9 -> 48605.135 | F33: =E9 -> 393785.82 | G33: =F9 -> 756480.4 | H33: =IFERROR(IRR(B33:G33),"N/A") -> 0.64174473
A34: PESSIMISTA | B34: =-$B$3 -> -65700 | C34: =B10 -> -7169.233 | D34: =C10 -> -224082.75 | E34: =D10 -> -408067.36 | F34: =E10 -> -277945.13 | G34: =F10 -> -392861.9 | H34: =IFERROR(IRR(B34:G34),"N/A") -> N/A

Sheet Projeção 5 Anos
A1: PROJEÇÃO 5 ANOS (2026-2030) — Visão para investidor
A2: Anos 1-3: dados detalhados da Projeção Mensal | Anos 4-5: high-level com crescimento anual
A4: Item | B4: 2026 | E4: 2027 | H4: 2028 | K4: 2029 | N4: 2030
B5: OTI | C5: REA | D5: PES | E5: OTI | F5: REA | G5: PES | H5: OTI | I5: REA | J5: PES | K5: OTI | L5: REA | M5: PES | N5: OTI | O5: REA | P5: PES
A6: 💰 RECEITA POR FONTE
A7: Receita Afiliado | B7: ='DRE Anual'!B6 -> 3836.16 | C7: ='DRE Anual'!C6 -> 524.6696 | D7: ='DRE Anual'!D6 -> 32.95875 | E7: ='DRE Anual'!E6 -> 83850.795 | F7: ='DRE Anual'!F6 -> 5567.1252 | G7: ='DRE Anual'!G6 -> 204.2865 | H7: ='DRE Anual'!H6 -> 298637.55 | I7: ='DRE Anual'!I6 -> 12378.22 | J7: ='DRE Anual'!J6 -> 310.10925 | K7: =H7*(1+Premissas!$D$57) -> 388228.82 | L7: =I7*(1+Premissas!$E$57) -> 14853.864 | M7: =J7*(1+Premissas!$F$57) -> 341.12018 | N7: =K7*(1+Premissas!$D$57) -> 504697.46 | O7: =L7*(1+Premissas!$E$57) -> 17824.637 | P7: =M7*(1+Premissas!$F$57) -> 375.23219
A8: Receita Venda Direta | B8: ='DRE Anual'!B7 -> 0 | C8: ='DRE Anual'!C7 -> 0 | D8: ='DRE Anual'!D7 -> 0 | E8: ='DRE Anual'!E7 -> 275604 | F8: ='DRE Anual'!F7 -> 61425 | G8: ='DRE Anual'!G7 -> 3705 | H8: ='DRE Anual'!H7 -> 4207296 | I8: ='DRE Anual'!I7 -> 479640 | J8: ='DRE Anual'!J7 -> 13104 | K8: =H8*(1+Premissas!$D$58) -> 7783497.6 | L8: =I8*(1+Premissas!$E$58) -> 791406 | M8: =J8*(1+Premissas!$F$58) -> 15724.8 | N8: =K8*(1+Premissas!$D$58) -> 14399471 | O8: =L8*(1+Premissas!$E$58) -> 1305819.9 | P8: =M8*(1+Premissas!$F$58) -> 18869.76
A9: Receita SaaS Promoter | B9: ='DRE Anual'!B8 -> 0 | C9: ='DRE Anual'!C8 -> 0 | D9: ='DRE Anual'!D8 -> 0 | E9: ='DRE Anual'!E8 -> 15030 | F9: ='DRE Anual'!F8 -> 9108 | G9: ='DRE Anual'!G8 -> 2001 | H9: ='DRE Anual'!H8 -> 121050 | I9: ='DRE Anual'!I8 -> 61974 | J9: ='DRE Anual'!J8 -> 5796 | K9: =H9*(1+Premissas!$D$59) -> 338940 | L9: =I9*(1+Premissas!$E$59) -> 142540.2 | M9: =J9*(1+Premissas!$F$59) -> 7534.8 | N9: =K9*(1+Premissas!$D$59) -> 949032 | O9: =L9*(1+Premissas!$E$59) -> 327842.46 | P9: =M9*(1+Premissas!$F$59) -> 9795.24
A10: RECEITA TOTAL | B10: =B7+B8+B9 -> 3836.16 | C10: =C7+C8+C9 -> 524.6696 | D10: =D7+D8+D9 -> 32.95875 | E10: =E7+E8+E9 -> 374484.79 | F10: =F7+F8+F9 -> 76100.125 | G10: =G7+G8+G9 -> 5910.2865 | H10: =H7+H8+H9 -> 4626983.5 | I10: =I7+I8+I9 -> 553992.22 | ... P10: =P7+P8+P9 -> 29040.232
A12: 💸 CUSTOS TOTAIS
A13: Custos Operacionais + Tributos | B13: ='DRE Anual'!B9+'DRE Anual'!B10+'DRE Anual'!B12 -> -7455.1046 | C13: ='DRE Anual'!C9+'DRE Anual'!C10+'DRE Anual'!C12 -> -7234.8905 | D13: ='DRE Anual'!D9+'DRE Anual'!D10+'DRE Anual'!D12 -> -7202.1918 | E13: ='DRE Anual'!E9+'DRE Anual'!E10+'DRE Anual'!E12 -> -283263.67 | F13: ='DRE Anual'!F9+'DRE Anual'!F10+'DRE Anual'!F12 -> -234660.66 | G13: ='DRE Anual'!G9+'DRE Anual'!G10+'DRE Anual'!G12 -> -229993.03 | H13: ='DRE Anual'!H9+'DRE Anual'!H10+'DRE Anual'!H12 -> -1089046.7 | I13: ='DRE Anual'!I9+'DRE Anual'!I10+'DRE Anual'!I12 -> -505387.09 | J13: ='DRE Anual'!J9+'DRE Anual'!J10+'DRE Anual'!J12 -> -427277.47 | K13: =-Premissas!$D$60*12-K10*0.0655-IF((K10-Premissas!$D$60*12-K10*0.0655)>0,K10*0.0768,0) -> -1751067.8 | L13: =-Premissas!$E$60*12-L10*0.0655-IF((L10-Premissas!$E$60*12-L10*0.0655)>0,L10*0.0768,0) -> -555014.25 | M13: =-Premissas!$F$60*12-M10*0.0655-IF((M10-Premissas!$F$60*12-M10*0.0655)>0,M10*0.0768,0) -> -301545.85 | N13: =-Premissas!$D$61*12-N10*0.0655-IF((N10-Premissas!$D$61*12-N10*0.0655)>0,N10*0.0768,0) -> -3095910.4 | O13: =-Premissas!$E$61*12-O10*0.0655-IF((O10-Premissas!$E$61*12-O10*0.0655)>0,O10*0.0768,0) -> -895006.6 | P13: =-Premissas!$F$61*12-P10*0.0655-IF((P10-Premissas!$F$61*12-P10*0.0655)>0,P10*0.0768,0) -> -421902.14
A15: 📈 LUCRO LÍQUIDO | B15: =B10+B13 -> -3618.9446 | C15: =C10+C13 -> -6710.2209 | D15: =D10+D13 -> -7169.233 | E15: =E10+E13 -> 91221.124 | F15: =F10+F13 -> -158560.53 | G15: =G10+G13 -> -224082.75 | H15: =H10+H13 -> 3537936.8 | I15: =I10+I13 -> 48605.135 | ... P15: =P10+P13 -> -392861.9
A16: Margem Líquida (%) | B16: =IFERROR(B15/B10,0) -> -0.94337688 | C16: =IFERROR(C15/C10,0) -> -12.789422 | D16: =IFERROR(D15/D10,0) -> -217.52139 | E16: =IFERROR(E15/E10,0) -> 0.243591 | F16: =IFERROR(F15/F10,0) -> -2.0835778 | G16: =IFERROR(G15/G10,0) -> -37.914025 | H16: =IFERROR(H15/H10,0) -> 0.76463138 | I16: =IFERROR(I15/I10,0) -> 0.087736133 | ... P16: =IFERROR(P15/P10,0) -> -13.528194
A18: 💼 FLUXO DE CAIXA ACUMULADO (5 anos)
A19: (-) Investimento Inicial (ano 0) | B19: =-'Investimento Inicial'!$D$20 -> -65700
A20: Fluxo acumulado | B20: =-'Investimento Inicial'!$D$20+B15 -> -69318.945 | C20: =-'Investimento Inicial'!$D$20+C15 -> -72410.221 | D20: =-'Investimento Inicial'!$D$20+D15 -> -72869.233 | E20: =B20+E15 -> 21902.179 | F20: =C20+F15 -> -230970.75 | G20: =D20+G15 -> -296951.98 | H20: =E20+H15 -> 3559839 | I20: =F20+I15 -> -182365.62 | J20: =G20+J15 -> -705019.34 | K20: =H20+K15 -> 10319438 | L20: =I20+L15 -> 211420.2 | ... P20: =M20+P15 -> -1375826.4
A22: 💎 ARR (Annual Recurring Revenue) — SaaS apenas
A23: ARR (SaaS no ano) | B23: =B9 -> 0 | C23: =C9 -> 0 | D23: =D9 -> 0 | E23: =E9 -> 15030 | F23: =F9 -> 9108 | G23: =G9 -> 2001 | H23: =H9 -> 121050 | I23: =I9 -> 61974 | ... P23: =P9 -> 9795.24

Sheet Pitch Metrics
A1: PITCH METRICS — o que investidor olha
A2: Métricas-chave de SaaS para apresentação a investidores anjo / seed / Série A
A4: Métrica | B4: OTIMISTA | C4: REALISTA | D4: PESSIMISTA | E4: Benchmark / Meta
A5: ── UNIT ECONOMICS ──
A6: CAC (Custo de Aquisição) | B6: ='Métricas SaaS'!B11 -> 300 | C6: ='Métricas SaaS'!C11 -> 750 | D6: ='Métricas SaaS'!D11 -> -48000 | E6: < R$ 500 (saudável)
A7: LTV (Lifetime Value) | B7: ='Métricas SaaS'!B10 -> 1800 | C7: ='Métricas SaaS'!C10 -> 1980 | D7: ='Métricas SaaS'!D10 -> 575 | E7: > R$ 1.500 (bom)
A8: LTV / CAC ratio | B8: ='Métricas SaaS'!B12 -> 6 | C8: ='Métricas SaaS'!C12 -> 2.64 | D8: ='Métricas SaaS'!D12 -> -0.011979167 | E8: > 3x = saudável | > 5x = excelente
A9: CAC Payback (meses) | B9: ='Métricas SaaS'!B13 -> 3.3333333 | C9: ='Métricas SaaS'!C13 -> 7.5757576 | D9: ='Métricas SaaS'!D13 -> -695.65217 | E9: < 12 meses (ideal)
A10: Churn mensal | B10: ='Métricas SaaS'!B9 -> 0.05 | C10: ='Métricas SaaS'!C9 -> 0.05 | D10: ='Métricas SaaS'!D9 -> 0.12 | E10: < 5% (B2B saudável) | < 8% (aceitável)
A12: ── CRESCIMENTO E TRAÇÃO ──
A13: MRR final (dez/28) | B13: ='Métricas SaaS'!B5 -> 17550 | C13: ='Métricas SaaS'!C5 -> 8316 | D13: ='Métricas SaaS'!D5 -> 483 | E13: Métrica-chave para Série A: > R$ 50k MRR
A14: MRR final 2030 (estimado) | B14: ='Projeção 5 Anos'!N9/12 -> 79086 | C14: ='Projeção 5 Anos'!O9/12 -> 27320.205 | D14: ='Projeção 5 Anos'!P9/12 -> 816.27 | E14: ARR/12 → escala em 5 anos
A15: ARR final 2030 | B15: ='Projeção 5 Anos'!N9 -> 949032 | C15: ='Projeção 5 Anos'!O9 -> 327842.46 | D15: ='Projeção 5 Anos'!P9 -> 9795.24 | E15: Drives valuation no múltiplo de receita
A16: Crescimento ARR 2028→2030 (CAGR) | B16: =IFERROR(('Projeção 5 Anos'!N9/'Projeção 5 Anos'!H9)^(1/2)-1,0) -> 1.8 | C16: =IFERROR(('Projeção 5 Anos'!O9/'Projeção 5 Anos'!I9)^(1/2)-1,0) -> 1.3 | D16: =IFERROR(('Projeção 5 Anos'!P9/'Projeção 5 Anos'!J9)^(1/2)-1,0) -> 0.3 | E16: > 80% a.a. (excelente para SaaS early)
A18: ── SAÚDE FINANCEIRA ──
A19: Receita Total 2030 | B19: ='Projeção 5 Anos'!N10 -> 15853200 | C19: ='Projeção 5 Anos'!O10 -> 1651487 | D19: ='Projeção 5 Anos'!P10 -> 29040.232
A20: Lucro Líquido 2030 | B20: ='Projeção 5 Anos'!N15 -> 12757290 | C20: ='Projeção 5 Anos'!O15 -> 756480.4 | D20: ='Projeção 5 Anos'!P15 -> -392861.9
A21: Margem Líquida 2030 | B21: ='Projeção 5 Anos'!N16 -> 0.80471385 | C21: ='Projeção 5 Anos'!O16 -> 0.45806016 | D21: ='Projeção 5 Anos'!P16 -> -13.528194 | E21: > 20% (saudável SaaS maduro)
A22: Rule of 40 (Growth + Margin) | B22: =B16+B21 -> 2.6047139 | C22: =C16+C21 -> 1.7580602 | D22: =D16+D21 -> -13.228194 | E22: > 40% = SaaS saudável (regra do Bessemer)
A24: ── BURN & RUNWAY ──
A25: Burn rate médio Fase 3 (R$/mês) | B25: =IF('DRE Anual'!H11<0,-'DRE Anual'!H11/12,0) -> 0 | C25: =IF('DRE Anual'!I11<0,-'DRE Anual'!I11/12,0) -> 0 | D25: =IF('DRE Anual'!J11<0,-'DRE Anual'!J11/12,0) -> 34005.614 | E25: Pode ser zero se receita > custo
A26: Pico de cash burn | B26: =MIN('Projeção Mensal'!B24:AC24) -> -6657.8342 | C26: =MIN('Projeção Mensal'!B48:AC48) -> -232137.84 | D26: =MIN('Projeção Mensal'!B72:AC72) -> -639319.34 | E26: Quanto capital precisa ter no pior momento
A28: 📝 NOTAS PARA O PITCH:
A29: • LTV/CAC > 3x e CAC Payback < 12 meses são as duas métricas mais importantes para SaaS B2B
A30: • Rule of 40 é o que VCs de série A+ olham para validar saúde do negócio em SaaS
A31: • Investidor anjo / seed se importa mais com tração atual e capacidade de execução do que com projeção 5 anos
A32: • Use o cenário REALISTA como base para discussão; OTIMISTA mostra potencial; PESSIMISTA mostra resiliência
A33: • MRR e ARR são as métricas-chave para qualquer SaaS — substituem 'receita' nas conversas com VCs

Sheet Valuation
A1: VALUATION ESTIMADO — múltiplos SaaS B2B Brasil
A2: Faixa de valuation baseada em múltiplos de ARR e Receita para SaaS B2B brasileiro
A4: 📚 REFERÊNCIAS DE MERCADO (SaaS B2B Brasil — 2024-2025)
A5: Múltiplo ARR — SaaS B2B Early-stage Brasil | B5: 4x – 8x | C5: Empresas <R$ 1M ARR, crescimento <100%
A6: Múltiplo ARR — SaaS B2B Growth Brasil | B6: 8x – 15x | C6: Empresas R$ 1-10M ARR, crescimento >80%
A7: Múltiplo Receita — Marketplace B2C Brasil | B7: 2x – 5x | C7: Modelo de transação (afiliado, venda direta)
A8: Rule of Thumb | B8: 5x ARR + 2x receita não-recorrente | C8: Mistura SaaS + transação
A11: 💰 VALUATION ESTIMADO POR CENÁRIO (final 2030)
A12: Métrica | B12: OTIMISTA | C12: REALISTA | D12: PESSIMISTA | E12: Múltiplo | F12: Comentário
A13: ARR 2030 (Receita SaaS) | B13: ='Projeção 5 Anos'!N9 -> 949032 | C13: ='Projeção 5 Anos'!O9 -> 327842.46 | D13: ='Projeção 5 Anos'!P9 -> 9795.24 | E13: — | F13: Base do cálculo
A14: Receita não-SaaS 2030 | B14: ='Projeção 5 Anos'!N7+'Projeção 5 Anos'!N8 -> 14904168 | C14: ='Projeção 5 Anos'!O7+'Projeção 5 Anos'!O8 -> 1323644.5 | D14: ='Projeção 5 Anos'!P7+'Projeção 5 Anos'!P8 -> 19244.992 | E14: — | F14: Afiliado + Venda Direta
A16: Cenários de valuation aplicados
A17: Cenário CONSERVADOR (4x ARR + 2x não-SaaS) | B17: =B13*4+B14*2 -> 33604464 | C17: =C13*4+C14*2 -> 3958658.9 | D17: =D13*4+D14*2 -> 77670.944 | E17: 4x / 2x | F17: Mercado em baixa, captação difícil
A18: Cenário REALISTA (8x ARR + 3x não-SaaS) | B18: =B13*8+B14*3 -> 52304760 | C18: =C13*8+C14*3 -> 6593673.3 | D18: =D13*8+D14*3 -> 136096.9 | E18: 8x / 3x | F18: Mercado normal, captação saudável
A19: Cenário OTIMISTA (12x ARR + 4x não-SaaS) | B19: =B13*12+B14*4 -> 71005056 | C19: =C13*12+C14*4 -> 9228687.7 | D19: =D13*12+D14*4 -> 194522.85 | E19: 12x / 4x | F19: Mercado em alta, tração comprovada
A21: 📝 IMPORTANTE PARA O PITCH
A22: 1. Valuation NUNCA é uma promessa — é uma estimativa baseada em múltiplos do mercado público + comps.
A23: 2. SaaS B2B em fase early (pré-R$ 1M ARR) tem variância gigante. Investidor anjo paga 4-6x ARR; estratégico paga 10-15x.
A24: 3. Em uma captação seed, o valuation é function da NEGOCIAÇÃO e da QUALIDADE DO TIME, não só do Excel.
A25: 4. ARR é a métrica REI. Mais que receita total, o investidor olha quanto da sua receita é RECORRENTE.
A26: 5. Para captar em 2027-2028: foque em chegar a R$ 30k+ MRR no REA antes de pedir valuation generoso.
